Workbook

Sheet Panduan
A1: Bank Soal — Jejak Inderasakti: Jelajah Pulau Penyengat
A2: Disusun 2026-09-20 · sesuai skema tabel `questions` di Architecture Plan dan aturan komposisi soal di About Game / Design Document.
A4: 1) Struktur & jumlah soal
A5: Bank soal berisi 66 butir: 60 soal situs (12 per situs × 5 situs) + 6 soal cadangan lintas situs, sesuai target di dokumen About Game ('60 soal situs + 6 soal cadangan'). Semua soal sudah bilingual (Indonesia & Inggris) dan siap dikonversi langsung menjadi seed/questions.json.
A7: 2) Kenapa 12 soal per situs dibagi 5 Mudah / 4 Sedang / 3 Sulit?
A8: Komposisi soal per stage di About Game menuntut sampai 2 soal Mudah dalam satu sesi (mis. room SD stage 1: M,M,S), sementara soal Sulit hanya muncul mulai stage 2 ke atas dan hanya untuk jenjang SMP/SMA. Proporsi 5/4/3 memberi cadangan paling besar pada level yang paling sering dipakai (Mudah), cukup untuk level Sedang yang dipakai di semua jenjang, dan tetap menyediakan variasi pada level Sulit yang levelnya lebih jarang tapi tetap penting untuk jenjang atas. Proporsi ini sama untuk kelima situs supaya server bisa memilih soal dengan aturan yang konsisten.
A10: 3) Keterbatasan yang perlu diketahui panitia
A11: Dengan hanya 5 soal Mudah per situs dan maksimal 5 room berjalan bersamaan yang masing-masing bisa butuh 2 soal Mudah, kemungkinan ada soal Mudah yang terpakai di lebih dari satu room dalam sesi yang sama — ini sesuai catatan Architecture Plan bahwa 5 room serentak 'tidak mendapat set yang PERSIS sama', bukan janji bahwa semua soal selalu unik antar-room. Jika ingin memperkecil pengulangan, tambahkan lebih banyak soal Mudah & Sedang pasca-Kamis (lihat bagian 7).
A13: 4) Struktur kolom (mengikuti tabel `questions` di Architecture Plan)
A14: • id — kode unik, format M{no situs}-{urutan} untuk soal situs (contoh M1-01) dan X-{urutan} untuk soal cadangan lintas situs.
A15: • site / site_name — nomor situs (1 Masjid Raya, 2 Makam Engku Putri & RAH, 3 Istana Kantor, 4 Gedung Tabib, 5 Perigi Puteri, 0 = lintas situs/cadangan).
A16: • level / level_name — 1 Mudah, 2 Sedang, 3 Sulit, sesuai tabel Aturan Tingkat Kesulitan di About Game.
... A44: • 'Ringkasan' — rekap jumlah soal per situs & level dengan formula COUNTIFS, untuk memeriksa cepat apakah distribusi masih sesuai target 5/4/3 setiap kali sheet Bank Soal diedit.

Sheet Bank Soal
A1: id | B1: site | C1: site_name | D1: level | E1: level_name | F1: type | G1: timer_detik | H1: poin_dasar | I1: prompt_id | J1: prompt_en | K1: opsi_a_id | L1: opsi_a_en | M1: opsi_b_id | N1: opsi_b_en | O1: opsi_c_id | P1: opsi_c_en | Q1: opsi_d_id | R1: opsi_d_en | S1: jawaban_benar | T1: penjelasan_id | U1: penjelasan_en | V1: sumber | W1: status_validasi | X1: active
A2: M1-01 | B2: 1 | C2: Masjid Raya | D2: 1 | E2: Mudah | F2: mc | G2: 15 | H2: 500 | I2: Berapa jumlah kubah di atap Masjid Raya Sultan Riau? | J2: How many domes does the Masjid Raya Sultan Riau have on its roof? | K2: 9 | L2: 9 | M2: 13 | N2: 13 | O2: 17 | P2: 17 | Q2: 21 | R2: 21 | S2: B | T2: Masjid ini memiliki 13 kubah yang tersusun berbaris di atasnya. | U2: The mosque has 13 domes arranged in rows on its roof. | V2: Wikipedia ID - Masjid Raya Sultan Riau; Republika 2020 | W2: Draf - perlu validasi | X2: TRUE
A3: M1-02 | B3: 1 | C3: Masjid Raya | D3: 1 | E3: Mudah | F3: mc | G3: 15 | H3: 500 | I3: Ada berapa menara di sudut-sudut Masjid Raya Sultan Riau? | J3: How many minarets stand at the corners of Masjid Raya Sultan Riau? | K3: 2 | L3: 2 | M3: 4 | N3: 4 | O3: 6 | P3: 6 | Q3: 8 | R3: 8 | S3: B | T3: Di setiap sudut masjid terdapat menara, totalnya 4 menara setinggi 18,9 meter. | U3: Each corner of the mosque has a minaret, four in total, each 18.9 metres tall. | V3: Wikipedia ID - Masjid Raya Sultan Riau | W3: Draf - perlu validasi | X3: TRUE
A4: M1-03 | B4: 1 | C4: Masjid Raya | D4: 1 | E4: Mudah | F4: tf | G4: 15 | H4: 500 | I4: Benar atau Salah: dinding Masjid Raya Sultan Riau memakai campuran putih telur sebagai bahan perekat. | J4: True or False: the walls of Masjid Raya Sultan Riau used egg white mixed in as a binding material. | K4: Benar | L4: True | M4: Salah | N4: False | S4: A | T4: Warga sekitar mengumpulkan putih telur untuk dicampur kapur dan pasir sebagai pengganti semen. | U4: Local residents collected egg whites to mix with lime and sand as a substitute for cement. | V4: Tempo.co 2021; CNN Indonesia 2024 | W4: Draf - perlu validasi | X4: TRUE
A5: M1-04 | B5: 1 | C5: Masjid Raya | D5: 1 | E5: Mudah | F5: mc | G5: 15 | H5: 500 | I5: Apa warna utama bangunan Masjid Raya Sultan Riau yang tampak dari kejauhan? | J5: What is the main colour of Masjid Raya Sultan Riau as seen from a distance? | K5: Kuning cerah berpadu hijau | L5: Bright yellow with green accents | M5: Putih polos | N5: Plain white | O5: Merah bata | P5: Brick red | Q5: Biru laut | R5: Sea blue | S5: A | T5: Masjid ini dikenal berwarna kuning cerah berpadu hijau, mencolok dari kejauhan. | U5: The mosque is known for its bright yellow colour with green accents, standing out from afar. | V5: Budaya-Indonesia.org; Disbudpar Tanjungpinang | W5: Draf - perlu validasi | X5: TRUE
A6: M1-05 | B6: 1 | C6: Masjid Raya | D6: 1 | E6: Mudah | F6: mc | G6: 15 | H6: 500 | I6: Berapa jumlah rumah sotoh yang berada di halaman Masjid Raya Sultan Riau? | J6: How many 'rumah sotoh' (open pavilions) stand in the mosque's courtyard? | K6: 1 | L6: 1 | M6: 2 | N6: 2 | O6: 3 | P6: 3 | Q6: 4 | R6: 4 | S6: B | T6: Ada dua rumah sotoh di halaman masjid, untuk musafir menginap dan tempat bermusyawarah. | U6: Two rumah sotoh stand in the courtyard, used for travellers to stay and for community meetings. | V6: Wikipedia ID - Masjid Raya Sultan Riau | W6: Draf - perlu validasi | X6: TRUE
A7: M1-06 | B7: 1 | C7: Masjid Raya | D7: 2 | E7: Sedang | F7: mc | G7: 20 | H7: 750 | I7: Jika jumlah kubah (13) dan menara (4) Masjid Raya Sultan Riau dijumlahkan, angka 17 itu melambangkan apa? | J7: If the mosque's domes (13) and minarets (4) are added together to make 17, what does that number symbolise? | K7: Jumlah wali songo | L7: The nine Wali Songo | M7: Jumlah rakaat sholat fardu sehari semalam | N7: The number of daily obligatory prayer cycles (rakaat) | O7: Jumlah tahun pembangunan | P7: The number of years of construction | Q7: Jumlah kerajaan Melayu | R7: The number of Malay kingdoms | S7: B | T7: Total 17 kubah dan menara dimaknai sebagai jumlah rakaat sholat fardu yang dikerjakan umat Islam tiap hari. | U7: The total of 17 domes and minarets is meant to symbolise the 17 daily obligatory prayer cycles in Islam. | V7: CNN Indonesia 2024; Disbudpar Tanjungpinang | W7: Draf - perlu validasi | X7: TRUE
A8: M1-07 | B8: 1 | C8: Masjid Raya | D8: 2 | E8: Sedang | F8: mc | G8: 20 | H8: 750 | I8: Siapa Yang Dipertuan Muda yang memerintahkan renovasi Masjid Raya ke bentuk megah yang terlihat sekarang pada 1832? | J8: Which Yang Dipertuan Muda ordered the mosque's 1832 renovation into the grand form seen today? | K8: Raja Ali Haji | L8: Raja Ali Haji | M8: Raja Abdurrahman (YDM VII) | N8: Raja Abdurrahman (7th Yang Dipertuan Muda) | O8: Raja Haji Fisabilillah | P8: Raja Haji Fisabilillah | Q8: Raja Daud | R8: Raja Daud | S8: B | T8: Raja Abdurrahman, Yang Dipertuan Muda Riau VII, mengajak warga bergotong royong merenovasi masjid ke bentuk sekarang pada 1832. | U8: Raja Abdurrahman, the 7th Yang Dipertuan Muda of Riau, led the community effort to renovate the mosque into its present form in 1832. | V8: Koreksi riset About Game (Kemdikbud 2018); budaya-indonesia.org | W8: Draf - perlu validasi | X8: TRUE
A9: M1-08 | B9: 1 | C9: Masjid Raya | D9: 2 | E9: Sedang | F9: mc | G9: 20 | H9: 750 | I9: Apa fungsi utama rumah sotoh di halaman Masjid Raya Sultan Riau? | J9: What was the main function of the rumah sotoh in the mosque's courtyard? | K9: Menyimpan senjata kerajaan | L9: Storing the kingdom's weapons | M9: Tempat musafir bermalam dan bermusyawarah | N9: A place for travellers to stay and for community meetings | O9: Rumah tinggal sultan | P9: The sultan's residence | Q9: Tempat memandikan jenazah | R9: A place to wash the deceased | S9: B | T9: Rumah sotoh berfungsi sebagai tempat singgah musafir sekaligus lokasi musyawarah warga. | U9: The rumah sotoh served as a resting place for travellers and as a venue for community discussions. | V9: Wikipedia ID - Masjid Raya Sultan Riau | W9: Draf - perlu validasi | X9: TRUE
A10: M1-09 | B10: 1 | C10: Masjid Raya | D10: 2 | E10: Sedang | F10: mc | G10: 20 | H10: 750 | I10: Apa nama galeri di dalam Masjid Raya yang menyimpan naskah kuno tulisan tangan? | J10: What is the name of the gallery inside Masjid Raya that houses handwritten ancient manuscripts? | K10: Galeri Kutubkhanah | L10: Kutubkhanah Gallery | M10: Balai Adat | N10: Balai Adat | O10: Rumah Baca | P10: Rumah Baca (Reading House) | Q10: Gedung Arsip | R10: Archive Building | S10: A | T10: Galeri Kutubkhanah atau perpustakaan Marhum Ahmadi menyimpan kitab-kitab tulisan tangan tentang ilmu pengetahuan. | U10: The Kutubkhanah Gallery, or Marhum Ahmadi library, holds handwritten manuscripts on various fields of knowledge. | V10: Gatra.com 2024 | W10: Draf - perlu validasi | X10: TRUE
A11: M1-10 | B11: 1 | C11: Masjid Raya | D11: 3 | E11: Sulit | F11: mc | G11: 25 | H11: 1000 | I11: Manakah urutan sejarah pembangunan Masjid Raya Sultan Riau yang PALING tepat? | J11: Which of these BEST describes the historical construction sequence of Masjid Raya Sultan Riau? | K11: Dibangun langsung megah dari batu pada 1832 tanpa bangunan sebelumnya | L11: Built directly as a grand stone structure in 1832 with no earlier building | M11: Awalnya bangunan sederhana berbahan kayu dan bata sejak awal abad ke-19, lalu direnovasi ke bentuk sekarang pada 1832 | N11: Originally a simple wood-and-brick structure from the early 19th century, later renovated into its present form in 1832 | O11: Dibangun oleh pemerintah kolonial pada abad ke-20 | P11: Built by the colonial government in the 20th century | Q11: Direnovasi pertama kali pada 1900-an | R11: First renovated in the 1900s | S11: B | T11: Masjid mulanya sederhana sejak awal abad ke-19, lalu direnovasi menjadi bentuk megah sekarang pada 1832 atas perintah Raja Abdurrahman. | U11: The mosque began as a simple structure in the early 19th century, then was renovated into its grand present form in 1832 under Raja Abdurrahman. | V11: Koreksi riset About Game; NU Online 2009; Republika 2020 | W11: Draf - perlu validasi | X11: TRUE
A12: M1-11 | B12: 1 | C12: Masjid Raya | D12: 3 | E12: Sulit | F12: mc | G12: 25 | H12: 1000 | I12: Mengapa Masjid Raya Sultan Riau disebut istimewa di antara peninggalan Kerajaan Riau-Lingga? | J12: Why is Masjid Raya Sultan Riau considered special among the Riau-Lingga Kingdom's remaining heritage sites? | K12: Karena satu-satunya masjid berkubah emas di Indonesia | L12: Because it is the only gold-domed mosque in Indonesia | M12: Karena masih berdiri utuh dan tetap dipakai warga beribadah hingga kini | N12: Because it still stands intact and is still used by residents for worship today | O12: Karena dibangun terakhir kali oleh Belanda | P12: Because it was last built by the Dutch | Q12: Karena tidak memiliki menara | R12: Because it has no minarets | S12: B | T12: Masjid ini dianggap satu-satunya peninggalan Kerajaan Riau-Lingga yang masih utuh dan tetap digunakan untuk ibadah. | U12: The mosque is considered the only intact remaining heritage of the Riau-Lingga Kingdom, still actively used for worship. | V12: Wikipedia ID - Masjid Raya Sultan Riau | W12: Draf - perlu validasi | X12: TRUE
A13: M1-12 | B13: 1 | C13: Masjid Raya | D13: 3 | E13: Sulit | F13: mc | G13: 25 | H13: 1000 | I13: Manakah pernyataan yang SALAH tentang Masjid Raya Sultan Riau? | J13: Which of these statements about Masjid Raya Sultan Riau is INCORRECT? | K13: Memiliki 13 kubah dan 4 menara | L13: It has 13 domes and 4 minarets | M13: Bahan perekat dindingnya memakai campuran putih telur | N13: Its wall binder includes a mixture of egg white | O13: Dibangun dari beton bertulang modern sejak awal berdiri | P13: It was built from modern reinforced concrete from the very start | Q13: Warna utamanya kuning berpadu hijau | R13: Its main colour is yellow with green accents | S13: C | T13: Masjid ini awalnya bangunan sederhana berbahan kayu dan bata; teknologi semen dan beton modern belum dikenal saat direnovasi pada 1832. | U13: The mosque was originally a simple wood-and-brick building; modern cement and concrete technology were not yet known when it was renovated in 1832. | V13: NU Online 2009; Tempo.co 2021 | W13: Draf - perlu validasi | X13: TRUE
A14: M2-01 | B14: 2 | C14: Makam Engku Putri & RAH | D14: 1 | E14: Mudah | F14: mc | G14: 15 | H14: 500 | I14: Siapa nama asli Engku Putri yang dimakamkan di kompleks ini? | J14: What is the birth name of Engku Putri, buried in this tomb complex? | K14: Raja Hamidah | L14: Raja Hamidah | M14: Raja Aisyah | N14: Raja Aisyah | O14: Raja Siti | P14: Raja Siti | Q14: Raja Fatimah | R14: Raja Fatimah | S14: A | T14: Engku Putri dikenal juga dengan nama Raja Hamidah, permaisuri Sultan Mahmud Riayat Syah III. | U14: Engku Putri is also known as Raja Hamidah, the consort of Sultan Mahmud Riayat Syah III. | V14: Disbudpar Tanjungpinang; Wikipedia ID - Engku Puteri Raja Hamidah | W14: Draf - perlu validasi | X14: TRUE
A15: M2-02 | B15: 2 | C15: Makam Engku Putri & RAH | D15: 1 | E15: Mudah | F15: mc | G15: 15 | H15: 500 | I15: Engku Putri adalah putri dari tokoh kerajaan bernama... | J15: Engku Putri was the daughter of which royal figure? | K15: Raja Ali Haji | L15: Raja Ali Haji | M15: Raja Haji Fisabilillah | N15: Raja Haji Fisabilillah | O15: Raja Ahmad | P15: Raja Ahmad | Q15: Raja Daud | R15: Raja Daud | S15: B | T15: Engku Putri (Raja Hamidah) adalah putri Raja Haji Fisabilillah, Yang Dipertuan Muda Riau IV. | U15: Engku Putri (Raja Hamidah) was the daughter of Raja Haji Fisabilillah, the 4th Yang Dipertuan Muda of Riau. | V15: Melayupedia.com; Disbudpar Tanjungpinang | W15: Draf - perlu validasi | X15: TRUE
A16: M2-03 | B16: 2 | C16: Makam Engku Putri & RAH | D16: 1 | E16: Mudah | F16: tf | G16: 15 | H16: 500 | I16: Benar atau Salah: Pulau Penyengat diberikan sebagai mahar/mas kawin kepada Engku Putri. | J16: True or False: Penyengat Island was given as a dowry to Engku Putri. | K16: Benar | L16: True | M16: Salah | N16: False | S16: A | T16: Menurut cerita yang berkembang, Pulau Penyengat diberikan sebagai mahar kepada Engku Putri pada awal abad ke-19. | U16: According to popular accounts, Penyengat Island was given as a dowry to Engku Putri in the early 19th century. | V16: Koreksi riset About Game (tahun tidak dipastikan, dipakai 'awal abad ke-19') | W16: Draf - perlu validasi | X16: TRUE
A17: M2-04 | B17: 2 | C17: Makam Engku Putri & RAH | D17: 1 | E17: Mudah | F17: mc | G17: 15 | H17: 500 | I17: Selain Engku Putri, tokoh pujangga apa yang juga dimakamkan di kompleks ini? | J17: Besides Engku Putri, which literary figure is also buried in this complex? | K17: Raja Ali Haji | L17: Raja Ali Haji | M17: Raja Kecik | N17: Raja Kecik | O17: Raja Ismail | P17: Raja Ismail | Q17: Raja Muhammad | R17: Raja Muhammad | S17: A | T17: Raja Ali Haji, pengarang Gurindam Dua Belas dan Pahlawan Nasional, dimakamkan di kompleks makam ini. | U17: Raja Ali Haji, author of Gurindam Dua Belas and a National Hero, is buried in this tomb complex. | V17: Tempo.co - Data Foto 2013; Wikipedia ID | W17: Draf - perlu validasi | X17: TRUE
A18: M2-05 | B18: 2 | C18: Makam Engku Putri & RAH | D18: 1 | E18: Mudah | F18: mc | G18: 15 | H18: 500 | I18: Raja Abdurrahman yang dimakamkan di kompleks ini menjabat sebagai... | J18: What title did Raja Abdurrahman, buried in this complex, hold? | K18: Yang Dipertuan Muda Riau VII | L18: 7th Yang Dipertuan Muda of Riau | M18: Tabib kerajaan | N18: The kingdom's royal physician | O18: Panglima laut | P18: Naval commander | Q18: Bendahara kerajaan | R18: Kingdom's treasurer | S18: A | T18: Raja Abdurrahman adalah Yang Dipertuan Muda Riau VII yang memerintahkan renovasi Masjid Raya pada 1832. | U18: Raja Abdurrahman was the 7th Yang Dipertuan Muda of Riau, who ordered the mosque's renovation in 1832. | V18: Koreksi riset About Game; budaya-indonesia.org | W18: Draf - perlu validasi | X18: TRUE
A19: M2-06 | B19: 2 | C19: Makam Engku Putri & RAH | D19: 2 | E19: Sedang | F19: mc | G19: 20 | H19: 750 | I19: Apa fungsi 'regalia' kerajaan yang dijaga oleh Engku Putri semasa hidupnya? | J19: What was the function of the royal 'regalia' guarded by Engku Putri during her lifetime? | K19: Sebagai alat kebesaran wajib untuk penobatan Sultan agar sah menurut adat | L19: As ceremonial royal items required to legitimise a Sultan's coronation by custom | M19: Sebagai mas kawin untuk anaknya | N19: As a dowry for her child | O19: Sebagai perhiasan pribadi | P19: As personal jewellery | Q19: Sebagai alat berperang | R19: As weapons of war | S19: A | T19: Regalia terdiri dari cogan, tepak sirih, ketor, keris panjang, dan nobat, yang wajib ada saat pelantikan Sultan agar sah menurut adat. | U19: The regalia included a cogan, betel-nut set, ketor, long keris, and nobat drum, all required for a Sultan's coronation to be considered legitimate by custom. | V19: Wikipedia ID - Engku Puteri Raja Hamidah; Disbudpar Tanjungpinang | W19: Draf - perlu validasi | X19: TRUE
A20: M2-07 | B20: 2 | C20: Makam Engku Putri & RAH | D20: 2 | E20: Sedang | F20: mc | G20: 20 | H20: 750 | I20: Mengapa Raja Abdurrahman penting dalam sejarah Masjid Raya Sultan Riau? | J20: Why is Raja Abdurrahman important to the history of Masjid Raya Sultan Riau? | K20: Karena beliau memerintahkan renovasi masjid ke bentuk sekarang pada 1832 | L20: Because he ordered the mosque's renovation into its present form in 1832 | M20: Karena beliau membangun Istana Kantor | N20: Because he built Istana Kantor | O20: Karena beliau menulis Gurindam Dua Belas | P20: Because he wrote Gurindam Dua Belas | Q20: Karena beliau seorang tabib | R20: Because he was a royal physician | S20: A | T20: Sebagai Yang Dipertuan Muda Riau VII, Raja Abdurrahman mengajak warga bergotong royong merenovasi masjid pada 1832. | U20: As the 7th Yang Dipertuan Muda of Riau, Raja Abdurrahman led the community effort to renovate the mosque in 1832. | V20: Koreksi riset About Game | W20: Draf - perlu validasi | X20: TRUE
A21: M2-08 | B21: 2 | C21: Makam Engku Putri & RAH | D21: 2 | E21: Sedang | F21: mc | G21: 20 | H21: 750 | I21: Karya sastra apa yang teksnya tertulis di dinding bagian dalam kompleks makam ini? | J21: Which literary work is inscribed on the interior walls of this tomb complex? | K21: Kitab Ilmu Tabib | L21: Kitab Ilmu Tabib | M21: Gurindam Dua Belas | N21: Gurindam Dua Belas | O21: Kitab Pengetahuan Bahasa | P21: Kitab Pengetahuan Bahasa | Q21: Hikayat Hang Tuah | R21: Hikayat Hang Tuah | S21: B | T21: Di bagian dalam makam terdapat tulisan berisi pasal-pasal Gurindam Dua Belas karya Raja Ali Haji. | U21: The interior of the tomb bears inscriptions of the verses of Gurindam Dua Belas, written by Raja Ali Haji. | V21: Blog UIN Suka 2024 | W21: Draf - perlu validasi | X21: TRUE
A22: M2-09 | B22: 2 | C22: Makam Engku Putri & RAH | D22: 2 | E22: Sedang | F22: mc | G22: 20 | H22: 750 | I22: Apa hubungan kekerabatan antara Engku Putri dan Raja Ali Haji? | J22: What is the family relationship between Engku Putri and Raja Ali Haji? | K22: Engku Putri adalah bibi Raja Ali Haji | L22: Engku Putri was Raja Ali Haji's aunt | M22: Mereka tidak memiliki hubungan keluarga | N22: They have no family relation | O22: Engku Putri adalah anak dari Raja Ali Haji | P22: Engku Putri was Raja Ali Haji's child | Q22: Raja Ali Haji adalah kakek Engku Putri | R22: Raja Ali Haji was Engku Putri's grandfather | S22: A | T22: Engku Putri dan Raja Ahmad (ayah Raja Ali Haji) sama-sama anak Raja Haji Fisabilillah, sehingga Engku Putri adalah bibi Raja Ali Haji. | U22: Engku Putri and Raja Ahmad (Raja Ali Haji's father) were both children of Raja Haji Fisabilillah, making Engku Putri the aunt of Raja Ali Haji. | V22: Kembara UMM; disimpulkan dari silsilah Raja Haji Fisabilillah | W22: Draf - perlu validasi | X22: TRUE
A23: M2-10 | B23: 2 | C23: Makam Engku Putri & RAH | D23: 3 | E23: Sulit | F23: mc | G23: 25 | H23: 1000 | I23: Manakah pernyataan yang SALAH tentang Raja Abdurrahman dalam game ini? | J23: Which statement about Raja Abdurrahman in this game is INCORRECT? | K23: Beliau adalah Yang Dipertuan Muda Riau VII | L23: He was the 7th Yang Dipertuan Muda of Riau | M23: Beliau memerintahkan renovasi Masjid Raya pada 1832 | N23: He ordered the mosque's renovation in 1832 | O23: Beliau adalah penulis Gurindam Dua Belas | P23: He was the author of Gurindam Dua Belas | Q23: Beliau dimakamkan di kompleks makam bangsawan Pulau Penyengat | R23: He is buried in the noble tomb complex on Penyengat Island | S23: C | T23: Gurindam Dua Belas ditulis oleh Raja Ali Haji, bukan Raja Abdurrahman. | U23: Gurindam Dua Belas was written by Raja Ali Haji, not Raja Abdurrahman. | V23: Koreksi riset About Game | W23: Draf - perlu validasi | X23: TRUE
A24: M2-11 | B24: 2 | C24: Makam Engku Putri & RAH | D24: 3 | E24: Sulit | F24: mc | G24: 25 | H24: 1000 | I24: Mengapa kompleks makam Engku Putri penting dalam sistem pemerintahan Kerajaan Riau-Lingga, bukan hanya sebagai tempat pemakaman? | J24: Why was Engku Putri's tomb complex important to the Riau-Lingga Kingdom's governance, beyond being a burial site? | K24: Karena regalia kerajaan dijaga olehnya, syarat sahnya penobatan Sultan | L24: Because she guarded the royal regalia, required for a Sultan's coronation to be valid | M24: Karena di sinilah pusat perdagangan kerajaan | N24: Because it was the kingdom's trade centre | O24: Karena di sinilah lokasi benteng pertahanan utama | P24: Because it was the main defence fortress | Q24: Karena di sinilah pabrik senjata kerajaan | R24: Because it was the kingdom's weapons factory | S24: A | T24: Engku Putri memegang regalia kerajaan yang menjadi syarat sah pelantikan Sultan menurut adat, menjadikannya tokoh penting dalam pemerintahan. | U24: Engku Putri held the royal regalia required by custom to legitimise a Sultan's coronation, making her a key figure in governance. | V24: Wikipedia ID - Engku Puteri Raja Hamidah | W24: Draf - perlu validasi | X24: TRUE
A25: M2-12 | B25: 2 | C25: Makam Engku Putri & RAH | D25: 3 | E25: Sulit | F25: mc | G25: 25 | H25: 1000 | I25: Urutan peristiwa yang benar terkait dua tokoh di stage ini adalah... | J25: Which is the correct sequence of events involving the two figures in this stage? | K25: Raja Abdurrahman merenovasi masjid pada 1832, Engku Putri wafat pada 1844 | L25: Raja Abdurrahman renovated the mosque in 1832; Engku Putri passed away in 1844 | M25: Engku Putri merenovasi masjid, Raja Abdurrahman menulis Gurindam 12 | N25: Engku Putri renovated the mosque; Raja Abdurrahman wrote Gurindam 12 | O25: Keduanya adalah tabib kerajaan | P25: Both were royal physicians | Q25: Keduanya memerintah sebagai Sultan pada waktu yang sama | R25: Both ruled as Sultan at the same time | S25: A | T25: Raja Abdurrahman merenovasi Masjid Raya pada 1832; Engku Putri wafat pada 7 Juli 1844 di Pulau Penyengat. | U25: Raja Abdurrahman renovated Masjid Raya in 1832; Engku Putri passed away on 7 July 1844 on Penyengat Island. | V25: Disbudpar Tanjungpinang; Koreksi riset About Game | W25: Draf - perlu validasi | X25: TRUE
A26: M3-01 | B26: 3 | C26: Istana Kantor | D26: 1 | E26: Mudah | F26: mc | G26: 15 | H26: 500 | I26: Istana Kantor merupakan kediaman dan kantor kerja dari... | J26: Istana Kantor served as the residence and workplace of... | K26: Raja Ali, Yang Dipertuan Muda VIII | L26: Raja Ali, the 8th Yang Dipertuan Muda | M26: Raja Abdurrahman | N26: Raja Abdurrahman | O26: Raja Daud | P26: Raja Daud | Q26: Engku Putri | R26: Engku Putri | S26: A | T26: Istana Kantor dibangun sebagai kediaman sekaligus kantor kerja Raja Ali, Yang Dipertuan Muda Riau-Lingga VIII. | U26: Istana Kantor was built as the residence and workplace of Raja Ali, the 8th Yang Dipertuan Muda of Riau-Lingga. | V26: Wikipedia ID - Istana Raja Ali Marhum; DisBud Kepri | W26: Draf - perlu validasi | X26: TRUE
A27: M3-02 | B27: 3 | C27: Istana Kantor | D27: 1 | E27: Mudah | F27: mc | G27: 15 | H27: 500 | I27: Istana Kantor dikelilingi oleh... | J27: What surrounds Istana Kantor? | K27: Parit air | L27: A water moat | M27: Tembok keliling dengan tiga pintu masuk | N27: A perimeter wall with three entrance gates | O27: Hutan bakau | P27: A mangrove forest | Q27: Pagar bambu | R27: A bamboo fence | S27: B | T27: Seluruh areal istana dibatasi tembok keliling dengan tiga pintu masuk dari arah barat, utara, dan timur. | U27: The whole palace grounds are enclosed by a perimeter wall with three entrance gates from the west, north, and east. | V27: DisBud Kepri; Kemdikbud - budaya.data.kemdikbud.go.id | W27: Draf - perlu validasi | X27: TRUE
A28: M3-03 | B28: 3 | C28: Istana Kantor | D28: 1 | E28: Mudah | F28: mc | G28: 15 | H28: 500 | I28: Berapa lantai bangunan utama Istana Kantor yang masih berdiri sekarang? | J28: How many storeys does the surviving main building of Istana Kantor have? | K28: Satu lantai | L28: One storey | M28: Dua lantai | N28: Two storeys | O28: Tiga lantai | P28: Three storeys | Q28: Empat lantai | R28: Four storeys | S28: B | T28: Bangunan utama yang tersisa adalah bangunan bertingkat dua. | U28: The surviving main building has two storeys. | V28: Wikipedia ID - Istana Raja Ali Marhum | W28: Draf - perlu validasi | X28: TRUE
A29: M3-04 | B29: 3 | C29: Istana Kantor | D29: 1 | E29: Mudah | F29: tf | G29: 15 | H29: 500 | I29: Benar atau Salah: salah satu pintu gerbang Istana Kantor berfungsi sebagai pos penjagaan dan pengintaian. | J29: True or False: one of Istana Kantor's gates functioned as a guard and lookout post. | K29: Benar | L29: True | M29: Salah | N29: False | S29: A | T29: Pintu gapura di sisi barat berbentuk gapura berlantai dua yang berfungsi sebagai pos penjagaan dan pengintaian. | U29: The western gate is a two-storey gapura that served as a guard and lookout post. | V29: DisBud Kepri; Kemdikbud | W29: Draf - perlu validasi | X29: TRUE
A30: M3-05 | B30: 3 | C30: Istana Kantor | D30: 1 | E30: Mudah | F30: mc | G30: 15 | H30: 500 | I30: Sekitar tahun berapa Raja Ali memerintah sebagai Yang Dipertuan Muda VIII dan menempati Istana Kantor? | J30: Around which years did Raja Ali rule as the 8th Yang Dipertuan Muda and occupy Istana Kantor? | K30: 1700-an | L30: 1700s | M30: 1780-an | N30: 1780s | O30: 1844-1857 | P30: 1844-1857 | Q30: 1900-an | R30: 1900s | S30: C | T30: Raja Ali, Yang Dipertuan Muda VIII, memerintah dan tinggal di Istana Kantor pada rentang 1844-1857. | U30: Raja Ali, the 8th Yang Dipertuan Muda, ruled and lived at Istana Kantor from 1844 to 1857. | V30: Koreksi riset About Game (rentang 1844-1857); Wikipedia ID | W30: Draf - perlu validasi | X30: TRUE
A31: M3-06 | B31: 3 | C31: Istana Kantor | D31: 2 | E31: Sedang | F31: mc | G31: 20 | H31: 750 | I31: Apa gaya arsitektur yang tampak pada bangunan Istana Kantor menurut kajian arsitektur? | J31: What architectural style does research identify in Istana Kantor's building? | K31: Murni gaya Melayu tradisional tanpa pengaruh luar | L31: Purely traditional Malay style with no outside influence | M31: Perpaduan pengaruh Eropa (kolonial) dengan Melayu | N31: A blend of European (colonial) influence with Malay style | O31: Gaya arsitektur Tiongkok klasik | P31: Classical Chinese architectural style | Q31: Gaya arsitektur Timur Tengah murni | R31: Purely Middle Eastern architectural style | S31: B | T31: Kajian arsitektur menyebut Istana Kantor sebagai akulturasi Melayu dengan pengaruh Eropa, Timur Tengah, dan India. | U31: Architectural studies describe Istana Kantor as a Malay acculturation with European, Middle Eastern, and Indian influences. | V31: Koreksi riset About Game (SIAR UMS 2022) | W31: Draf - perlu validasi | X31: TRUE
A32: M3-07 | B32: 3 | C32: Istana Kantor | D32: 2 | E32: Sedang | F32: mc | G32: 20 | H32: 750 | I32: Apa fungsi pintu gerbang yang mengarah ke kolam pemandian di Istana Kantor? | J32: What was the function of the gate leading to the bathing pool at Istana Kantor? | K32: Sebagai pintu darurat | L32: An emergency exit | M32: Sebagai jalan menuju tempat pemandian | N32: A path leading to the bathing area | O32: Sebagai gudang senjata | P32: A weapons storehouse | Q32: Sebagai kandang kuda | R32: A horse stable | S32: B | T32: Salah satu pintu gerbang istana berfungsi sebagai jalan menuju kolam pemandian di area istana. | U32: One of the palace gates served as the path to the bathing pool within the palace grounds. | V32: Wikipedia ID - Istana Raja Ali Marhum | W32: Draf - perlu validasi | X32: TRUE
A33: M3-08 | B33: 3 | C33: Istana Kantor | D33: 2 | E33: Sedang | F33: mc | G33: 20 | H33: 750 | I33: Karya sastra terkenal apa yang ditulis di lingkungan Istana Kantor oleh Raja Ali Haji? | J33: Which famous literary work did Raja Ali Haji write within the Istana Kantor grounds? | K33: Kitab Ilmu Tabib | L33: Kitab Ilmu Tabib | M33: Gurindam Dua Belas | N33: Gurindam Dua Belas | O33: Hikayat Hang Tuah | P33: Hikayat Hang Tuah | Q33: Kitab Pengetahuan Bahasa | R33: Kitab Pengetahuan Bahasa | S33: B | T33: Raja Ali Haji menulis Gurindam Dua Belas di lingkungan Istana Kantor, selesai pada 1847. | U33: Raja Ali Haji wrote Gurindam Dua Belas within the Istana Kantor grounds, completing it in 1847. | V33: Peluangnews.id 2024 | W33: Draf - perlu validasi | X33: TRUE
A34: M3-09 | B34: 3 | C34: Istana Kantor | D34: 2 | E34: Sedang | F34: mc | G34: 20 | H34: 750 | I34: Apa yang terdapat di lantai pertama bangunan utama Istana Kantor? | J34: What is found on the first floor of Istana Kantor's main building? | K34: Perpustakaan dan ruang sholat | L34: A library and a prayer room | M34: Sumur dan kakus | N34: A well and a latrine | O34: Dapur dan lumbung | P34: A kitchen and a granary | Q34: Kandang hewan | R34: An animal pen | S34: B | T34: Pada lantai pertama bangunan, terdapat sumur di satu sisi dan kakus di sisi lainnya. | U34: On the first floor, there is a well on one side and a latrine on the other. | V34: Kemdikbud - budaya.data.kemdikbud.go.id | W34: Draf - perlu validasi | X34: TRUE
A35: M3-10 | B35: 3 | C35: Istana Kantor | D35: 3 | E35: Sulit | F35: mc | G35: 25 | H35: 1000 | I35: Manakah pernyataan yang PALING tepat membedakan Raja Ali (pemilik Istana Kantor) dan Raja Ali Haji (penulis Gurindam 12)? | J35: Which statement BEST distinguishes Raja Ali (owner of Istana Kantor) from Raja Ali Haji (author of Gurindam 12)? | K35: Keduanya adalah orang yang sama | L35: They are the same person | M35: Raja Ali adalah Yang Dipertuan Muda VIII pemilik Istana Kantor, sedangkan Raja Ali Haji adalah pujangga yang menulis Gurindam 12 di lingkungan istana itu | N35: Raja Ali was the 8th Yang Dipertuan Muda who owned Istana Kantor, while Raja Ali Haji was the scholar who wrote Gurindam 12 within its grounds | O35: Raja Ali Haji adalah tabib kerajaan | P35: Raja Ali Haji was the kingdom's royal physician | Q35: Raja Ali adalah pendiri Masjid Raya | R35: Raja Ali was the founder of Masjid Raya | S35: B | T35: Meski namanya mirip, Raja Ali (YDM VIII, penguasa Istana Kantor) dan Raja Ali Haji (pujangga penulis Gurindam 12) adalah dua kerabat kerajaan yang berbeda. | U35: Despite similar names, Raja Ali (the 8th Yang Dipertuan Muda who ruled Istana Kantor) and Raja Ali Haji (the scholar who wrote Gurindam 12) were two different royal relatives. | V35: DisBud Kepri; Peluangnews.id 2024 | W35: Draf - perlu validasi | X35: TRUE
A36: M3-11 | B36: 3 | C36: Istana Kantor | D36: 3 | E36: Sulit | F36: mc | G36: 25 | H36: 1000 | I36: Manakah pernyataan yang SALAH tentang Istana Kantor? | J36: Which statement about Istana Kantor is INCORRECT? | K36: Merupakan kediaman dan kantor kerja Raja Ali YDM VIII | L36: It was the residence and office of Raja Ali, the 8th Yang Dipertuan Muda | M36: Dikelilingi tembok dengan tiga pintu masuk | N36: It is surrounded by a wall with three gates | O36: Beratap kubah emas bergaya Eropa mewah | P36: It has a luxurious European-style golden dome roof | Q36: Bangunan utamanya berlantai dua | R36: Its main building has two storeys | S36: C | T36: Istana Kantor tidak memiliki atap kubah emas; atapnya berbentuk limasan sederhana hasil pemugaran. | U36: Istana Kantor does not have a golden dome roof; its roof is a simple pyramidal (limasan) form from restoration work. | V36: Wikipedia ID - Istana Raja Ali Marhum | W36: Draf - perlu validasi | X36: TRUE
A37: M3-12 | B37: 3 | C37: Istana Kantor | D37: 3 | E37: Sulit | F37: mc | G37: 25 | H37: 1000 | I37: Mengapa Istana Kantor penting dalam sejarah kesusastraan Melayu, selain sebagai pusat pemerintahan? | J37: Beyond being a seat of government, why is Istana Kantor important to Malay literary history? | K37: Karena menjadi tempat lahir Raja Ali Haji | L37: Because Raja Ali Haji was born there | M37: Karena di lingkungan istana inilah Gurindam Dua Belas ditulis dan diselesaikan | N37: Because Gurindam Dua Belas was written and completed within the palace grounds | O37: Karena menjadi tempat penyimpanan Al-Quran tertua | P37: Because it stored the oldest Quran manuscript | Q37: Karena menjadi lokasi pembangunan pertama Masjid Raya | R37: Because it was where Masjid Raya was first built | S37: B | T37: Di lingkungan Istana Kantor inilah Raja Ali Haji menuliskan Gurindam Dua Belas, karya berisi nasihat hidup, bersahabat, dan memerintah negeri. | U37: It was within the Istana Kantor grounds that Raja Ali Haji wrote Gurindam Dua Belas, a work of advice on life, friendship, and governance. | V37: Peluangnews.id 2024 | W37: Draf - perlu validasi | X37: TRUE
A38: M4-01 | B38: 4 | C38: Gedung Tabib | D38: 1 | E38: Mudah | F38: mc | G38: 15 | H38: 500 | I38: Gedung Tabib dahulu merupakan kediaman seorang tokoh bernama... | J38: Gedung Tabib was once the residence of a figure named... | K38: Raja Daud | L38: Raja Daud | M38: Raja Ali Haji | N38: Raja Ali Haji | O38: Raja Abdurrahman | P38: Raja Abdurrahman | Q38: Engku Putri | R38: Engku Putri | S38: A | T38: Gedung Tabib adalah bekas kediaman Tabib Raja Daud, tabib tersohor pada masa Kerajaan Riau-Lingga. | U38: Gedung Tabib was once the residence of the royal physician Raja Daud, renowned during the Riau-Lingga Kingdom era. | V38: Goodnewsfromindonesia.id 2022; Kekunaan blog 2018 | W38: Draf - perlu validasi | X38: TRUE
A39: M4-02 | B39: 4 | C39: Gedung Tabib | D39: 1 | E39: Mudah | F39: mc | G39: 15 | H39: 500 | I39: Apa kondisi bangunan Gedung Tabib saat ini? | J39: What is the current condition of the Gedung Tabib building? | K39: Utuh dan masih beratap | L39: Intact and still roofed | M39: Tinggal kerangka dinding bata tanpa atap | N39: Only the brick wall frame remains, without a roof | O39: Sudah menjadi museum modern | P39: It has become a modern museum | Q39: Sudah rata dengan tanah | R39: It has been razed to the ground | S39: B | T39: Gedung Tabib kini hanya menyisakan susunan dinding bata tanpa atap, dengan pohon tumbuh merambat di sela-selanya. | U39: Gedung Tabib today is only a brick wall frame without a roof, with a tree growing through the gaps. | V39: Kekunaan blog 2018; National Geographic Indonesia | W39: Draf - perlu validasi | X39: TRUE
A40: M4-03 | B40: 4 | C40: Gedung Tabib | D40: 1 | E40: Mudah | F40: mc | G40: 15 | H40: 500 | I40: Apa fungsi utama Gedung Tabib pada masa Kerajaan Riau-Lingga? | J40: What was the main function of Gedung Tabib during the Riau-Lingga Kingdom era? | K40: Tempat berobat dan meracik obat herbal | L40: A place for treatment and preparing herbal medicine | M40: Gudang senjata | N40: A weapons storehouse | O40: Tempat penyimpanan padi | P40: A rice storage building | Q40: Balai pertemuan raja-raja | R40: A meeting hall for kings | S40: A | T40: Gedung ini digunakan Tabib Raja Daud untuk mengobati pasien dan meracik obat dari bahan-bahan herbal. | U40: The building was used by the physician Raja Daud to treat patients and prepare medicine from herbal ingredients. | V40: Goodnewsfromindonesia.id 2022 | W40: Draf - perlu validasi | X40: TRUE
...

Sheet Ringkasan
A1: Ringkasan Distribusi Bank Soal
A2: Semua angka di bawah dihitung otomatis dari sheet 'Bank Soal' (COUNTIFS) — akan ikut berubah bila baris soal ditambah/diedit.
A4: Situs | B4: Mudah | C4: Sedang | D4: Sulit | E4: Total
A5: Masjid Raya | B5: =COUNTIFS('Bank Soal'!$B$2:$B$67,1,'Bank Soal'!$D$2:$D$67,1) -> 5 | C5: =COUNTIFS('Bank Soal'!$B$2:$B$67,1,'Bank Soal'!$D$2:$D$67,2) -> 4 | D5: =COUNTIFS('Bank Soal'!$B$2:$B$67,1,'Bank Soal'!$D$2:$D$67,3) -> 3 | E5: =SUM(B5:D5) -> 12
A6: Makam Engku Putri & RAH | B6: =COUNTIFS('Bank Soal'!$B$2:$B$67,2,'Bank Soal'!$D$2:$D$67,1) -> 5 | C6: =COUNTIFS('Bank Soal'!$B$2:$B$67,2,'Bank Soal'!$D$2:$D$67,2) -> 4 | D6: =COUNTIFS('Bank Soal'!$B$2:$B$67,2,'Bank Soal'!$D$2:$D$67,3) -> 3 | E6: =SUM(B6:D6) -> 12
A7: Istana Kantor | B7: =COUNTIFS('Bank Soal'!$B$2:$B$67,3,'Bank Soal'!$D$2:$D$67,1) -> 5 | C7: =COUNTIFS('Bank Soal'!$B$2:$B$67,3,'Bank Soal'!$D$2:$D$67,2) -> 4 | D7: =COUNTIFS('Bank Soal'!$B$2:$B$67,3,'Bank Soal'!$D$2:$D$67,3) -> 3 | E7: =SUM(B7:D7) -> 12
A8: Gedung Tabib | B8: =COUNTIFS('Bank Soal'!$B$2:$B$67,4,'Bank Soal'!$D$2:$D$67,1) -> 5 | C8: =COUNTIFS('Bank Soal'!$B$2:$B$67,4,'Bank Soal'!$D$2:$D$67,2) -> 4 | D8: =COUNTIFS('Bank Soal'!$B$2:$B$67,4,'Bank Soal'!$D$2:$D$67,3) -> 3 | E8: =SUM(B8:D8) -> 12
A9: Perigi Puteri | B9: =COUNTIFS('Bank Soal'!$B$2:$B$67,5,'Bank Soal'!$D$2:$D$67,1) -> 5 | C9: =COUNTIFS('Bank Soal'!$B$2:$B$67,5,'Bank Soal'!$D$2:$D$67,2) -> 4 | D9: =COUNTIFS('Bank Soal'!$B$2:$B$67,5,'Bank Soal'!$D$2:$D$67,3) -> 3 | E9: =SUM(B9:D9) -> 12
A10: Lintas Situs (Cadangan) | B10: =COUNTIFS('Bank Soal'!$B$2:$B$67,0,'Bank Soal'!$D$2:$D$67,1) -> 2 | C10: =COUNTIFS('Bank Soal'!$B$2:$B$67,0,'Bank Soal'!$D$2:$D$67,2) -> 2 | D10: =COUNTIFS('Bank Soal'!$B$2:$B$67,0,'Bank Soal'!$D$2:$D$67,3) -> 2 | E10: =SUM(B10:D10) -> 6
A11: TOTAL | B11: =SUM(B5:B10) -> 27 | C11: =SUM(C5:C10) -> 22 | D11: =SUM(D5:D10) -> 17 | E11: =SUM(E5:E10) -> 66
A14: Target menurut About Game: 60 soal situs (12/situs) + 6 soal cadangan lintas situs = 66 total.
A15: Jumlah butir dengan status_validasi masih 'Draf - perlu validasi': | C15: =COUNTIF('Bank Soal'!$W$2:$W$67,"Draf - perlu validasi") -> 66
